Workbook
Name FilePath: Information!$Y$2

Sheet Interface
D2: Sandrone Stellar-conduct Artifact Optimizer | J2: Note: Yae Miko c1, Escoffier c0r1, Nicole dragon slayer, otherwise c0r0. Default RES is 10%
D4: Level | F4: 90/90 | J4: \
D5: Weapon | F5: Please Choose a weapon | J5: | Input
D6: ATK | F6: 1000 | J6: | Stats
D7: EM | F7: 125 | J7: | Here!!!
D8: CRIT DMG | F8: 1.5 | J8: /
D9: Artifact: Disenchantment in Deep Shadow (Unchangable)
D10: Team: | E10: Sandrone | G10: Choose your character | J10: Edit Team (dropdown), Sandrone is required.
D12: Your Damage: | F12: =TEXT(ROUND(Calculator!C92,0),"#,##0") & " - " & TEXT(ROUND(Calculator!C91,0),"#,##0") -> 14,753 - 15,529 | J12: TRUE | K12: =IF(NOT(J12), " i understood!", " <-- Click Here for Details") -> <-- Click Here for Details
D14: ___ System Optimized Build ___ | J14: Optimization based on your custom level, weapon, and team.
D15: Highest Damage Possible: | G15: =artifact_substat_cases!J2 -> 63385.325 | H15: Substats | J15: <- substats rolls amount
D16: Artifact %ATK: | G16: =artifact_substat_cases!AF2 -> 0.5247 | H16: =artifact_substat_cases!N2 & " rolls" -> 9 rolls | J16: buffs from artifacts substats only
D17: Artifact EM: | G17: =artifact_substat_cases!AG2 -> 69.93 | H17: =artifact_substat_cases!O2 & " rolls" -> 3 rolls
D18: Artifact %CRIT: | G18: =artifact_substat_cases!Z2 -> 2.0206 | H18: =artifact_substat_cases!P2 & " rolls" -> 18 rolls
D19: {="Main stats: " & _xlfn.TEXTJOIN("/",FALSE,IF(artifact_substat_cases!K2:M2="","None",artifact_substat_cases!K2:M2))} -> Main stats: %ATK/%ATK/%CRIT_DMG | J19: Sands/Globet/Circlet
D20: ___ Highest Total Stats ___
D21: ATK | E21: =artifact_substat_cases!AJ2 -> 2391.566 | F21: EM | H21: =artifact_substat_cases!AI2 -> 179.93 | J21: Highest Possible Stats
D22: CRIT_DMG | E22: =artifact_substat_cases!AK2 -> 2.5206 | F22: … | H22: … | J22: (after team buffs)
D24: =_xlfn.LET( _xlpm.atk_diff, artifact_substat_cases!W2-((F6-Calculator!B26)/Calculator!B26), _xlpm.crit_diff, artifact_substat_cases!Z2-F8, _xlpm.em_diff, artifact_substat_cases!AI2-F7, "You need " & TEXT(ABS(_xlpm.atk_diff),"0%") & " ATK " & IF(_xlpm.atk_diff<0,"less","more") & ", " & TEXT(ABS(_xlpm.crit_diff),"0%") & " CRIT DMG " & IF(_xlpm.crit_diff<0,"less","more") & ", and " & TEXT(ABS(_xlpm.em_diff),"#,##0") & " EM " & IF(_xlpm.em_diff<0,"less","more") ) -> You need 135% ATK more, 52% CRIT DMG more, and 55 EM more | J24: Read what you need more and reduce to increase your DMG
D25: =IFERROR("Summary: ["& ( IFERROR(ROUND(Calculator!$C$91/$G$15*100,1),0) ) &"%/100%] progress to best build possible!","Missing Info, Check your inputs") -> Summary: [24.5%/100%] progress to best build possible! | J25: % of how your build far away from best build possible!

Sheet #Changelog
A1: Credit:
A2: Optimizer calculator by yesn0t on Discord
A3: Sandrone artwork by Gleam霖时 on pixiv
B4: #ChangeLog
B5: Version | C5: Status | D5: Date | E5: Description
B6: v1.0 | C6: Released | D6: 46228 | E6: Released Sandrone Artifact Stats Optimizer Protection applied.

Sheet Calculator
A2: Multiplier | B2: Total | C2: QiQi | D2: Yae Miko | E2: Sandrone | F2: Escoffier | G2: Zhongli | H2: Nicole | I2: Bennett | J2: Kazuha | K2: Xilonen | L2: Beidou | M2: Diona | N2: Disenchantment in Deep Shadow
A3: %Stellar Reaction Base DMG Bonus | B3: =SUM(C3:N3) -> 0
A4: %Reaction Bonus | B4: =SUM(C4:P4) -> 1.8 | C4: 0.5 | D4: 0.5 | M4: 0.4 | N4: 0.4
A5: "Reaction Additive Base DMG Bonus" | B5: =SUM(C5:P5) -> 0
A6: Elevation Multiplier | B6: =SUM(C6:P6) -> 0
A7: RES Multiplier | B7: =SUM(C7:P7) -> -1.26 | F7: -0.15 | G7: -0.2 | J7: -0.4 | K7: -0.36 | L7: -0.15
A8: Flat ATK | B8: =SUM(C8:P8) -> 1400 | H8: 600 | I8: 800
A9: %ATK | B9: =SUM(C9:P9) -> 1.18 | F9: 0.32 | H9: 0.48 | I9: 0.2 | N9: 0.18
A10: %CRIT_DMG | B10: =SUM(C10:P10) -> 0
A11: EM | B11: =SUM(C11:P11) -> 400 | L11: 200 | M11: 200
C13: Slot 1 | D13: Slot 2 | E13: Slot 3 | F13: Slot 4 | G13: Artifact | H13: Weapon 1 | I13: Weapon 2 | J13: Weapon 3 | K13: Weapon 4 | L13: Weapon 5 | M13: Weapon 6
A14: Active Multiplier | B14: Total | C14: =IF(COUNTIF(Information!$T$3:$T$101,Interface!E10)>0,Interface!E10,"None") -> Sandrone | D14: =IF(COUNTIF(Information!$T$3:$T$101,Interface!F10)>0,Interface!F10,"None") -> None | E14: =IF(COUNTIF(Information!$T$3:$T$101,Interface!G10)>0,Interface!G10,"None") -> None | F14: =IF(COUNTIF(Information!$T$3:$T$101,Interface!H10)>0,Interface!H10,"None") -> None | G14: Disenchantment in Deep Shadow | H14: =IF(Interface!F5="Teaspoon of Transcendence","Teaspoon of Transcendence","None") -> None | I14: =IF(Interface!F5="A Thousand Blazing Suns","A Thousand Blazing Suns","None") -> None | J14: =IF(Interface!F5="Redhorn Stonethresher","Redhorn Stonethresher","None") -> None | K14: =IF(Interface!F5="Verdict","Verdict","None") -> None | L14: =IF(Interface!F5="Mailed Flower","Mailed Flower","None") -> None | M14: =IF(Interface!F5="Tidal Shadow","Tidal Shadow","None") -> None
A15: %Stellar Reaction Base DMG Bonus | B15: =SUM(C15:M15) -> 0 | C15: =_xlfn.LET( _xlpm.result, IFERROR(INDEX($C$3:$V$11, MATCH($A15,$A$3:$A$11,0), MATCH(C$14,$C$2:$V$2,0)), 0), IF(_xlpm.result=0, "", _xlpm.result) ) | D15: =_xlfn.LET( _xlpm.result, IFERROR(INDEX($C$3:$V$11, MATCH($A15,$A$3:$A$11,0), MATCH(D$14,$C$2:$V$2,0)), 0), IF(_xlpm.result=0, "", _xlpm.result) ) | E15: =_xlfn.LET( _xlpm.result, IFERROR(INDEX($C$3:$V$11, MATCH($A15,$A$3:$A$11,0), MATCH(E$14,$C$2:$V$2,0)), 0), IF(_xlpm.result=0, "", _xlpm.result) ) | F15: =_xlfn.LET( _xlpm.result, IFERROR(INDEX($C$3:$V$11, MATCH($A15,$A$3:$A$11,0), MATCH(F$14,$C$2:$V$2,0)), 0), IF(_xlpm.result=0, "", _xlpm.result) ) | G15: =_xlfn.LET( _xlpm.result, IFERROR(INDEX($C$3:$V$11, MATCH($A15,$A$3:$A$11,0), MATCH(G$14,$C$2:$V$2,0)), 0), IF(_xlpm.result=0, "", _xlpm.result) ) | H15: =IF(H$14="None","", 0 ) | I15: =IF(I$14="None","", 0 ) | J15: =IF(J$14="None","", 0 ) | K15: =IF(K$14="None","", 0 ) | L15: =IF(L$14="None","", 0 ) | M15: =IF(M$14="None","", 0 )
A16: %Reaction Bonus | B16: =SUM(C16:M16) -> 0.4 | C16: =_xlfn.LET( _xlpm.result, IFERROR(INDEX($C$3:$V$11, MATCH($A16,$A$3:$A$11,0), MATCH(C$14,$C$2:$V$2,0)), 0), IF(_xlpm.result=0, "", _xlpm.result) ) | D16: =_xlfn.LET( _xlpm.result, IFERROR(INDEX($C$3:$V$11, MATCH($A16,$A$3:$A$11,0), MATCH(D$14,$C$2:$V$2,0)), 0), IF(_xlpm.result=0, "", _xlpm.result) ) | E16: =_xlfn.LET( _xlpm.result, IFERROR(INDEX($C$3:$V$11, MATCH($A16,$A$3:$A$11,0), MATCH(E$14,$C$2:$V$2,0)), 0), IF(_xlpm.result=0, "", _xlpm.result) ) | F16: =_xlfn.LET( _xlpm.result, IFERROR(INDEX($C$3:$V$11, MATCH($A16,$A$3:$A$11,0), MATCH(F$14,$C$2:$V$2,0)), 0), IF(_xlpm.result=0, "", _xlpm.result) ) | G16: =_xlfn.LET( _xlpm.result, IFERROR(INDEX($C$3:$V$11, MATCH($A16,$A$3:$A$11,0), MATCH(G$14,$C$2:$V$2,0)), 0), IF(_xlpm.result=0, "", _xlpm.result) ) -> 0.4 | H16: =IF(H$14="None","", 48% ) | I16: =IF(I$14="None","", 0 ) | J16: =IF(J$14="None","", 0 ) | K16: =IF(K$14="None","", 0 ) | L16: =IF(L$14="None","", 0 ) | M16: =IF(M$14="None","", 0 )
A17: "Reaction Additive Base DMG Bonus" | B17: =SUM(C17:M17) -> 0 | C17: =_xlfn.LET( _xlpm.result, IFERROR(INDEX($C$3:$V$11, MATCH($A17,$A$3:$A$11,0), MATCH(C$14,$C$2:$V$2,0)), 0), IF(_xlpm.result=0, "", _xlpm.result) ) | D17: =_xlfn.LET( _xlpm.result, IFERROR(INDEX($C$3:$V$11, MATCH($A17,$A$3:$A$11,0), MATCH(D$14,$C$2:$V$2,0)), 0), IF(_xlpm.result=0, "", _xlpm.result) ) | E17: =_xlfn.LET( _xlpm.result, IFERROR(INDEX($C$3:$V$11, MATCH($A17,$A$3:$A$11,0), MATCH(E$14,$C$2:$V$2,0)), 0), IF(_xlpm.result=0, "", _xlpm.result) ) | F17: =_xlfn.LET( _xlpm.result, IFERROR(INDEX($C$3:$V$11, MATCH($A17,$A$3:$A$11,0), MATCH(F$14,$C$2:$V$2,0)), 0), IF(_xlpm.result=0, "", _xlpm.result) ) | G17: =_xlfn.LET( _xlpm.result, IFERROR(INDEX($C$3:$V$11, MATCH($A17,$A$3:$A$11,0), MATCH(G$14,$C$2:$V$2,0)), 0), IF(_xlpm.result=0, "", _xlpm.result) ) | H17: =IF(H$14="None","", 0 ) | I17: =IF(I$14="None","", 0 ) | J17: =IF(J$14="None","", 0 ) | K17: =IF(K$14="None","", 0 ) | L17: =IF(L$14="None","", 0 ) | M17: =IF(M$14="None","", 0 )
A18: Elevation Multiplier | B18: =SUM(C18:M18) -> 0 | C18: =_xlfn.LET( _xlpm.result, IFERROR(INDEX($C$3:$V$11, MATCH($A18,$A$3:$A$11,0), MATCH(C$14,$C$2:$V$2,0)), 0), IF(_xlpm.result=0, "", _xlpm.result) ) | D18: =_xlfn.LET( _xlpm.result, IFERROR(INDEX($C$3:$V$11, MATCH($A18,$A$3:$A$11,0), MATCH(D$14,$C$2:$V$2,0)), 0), IF(_xlpm.result=0, "", _xlpm.result) ) | E18: =_xlfn.LET( _xlpm.result, IFERROR(INDEX($C$3:$V$11, MATCH($A18,$A$3:$A$11,0), MATCH(E$14,$C$2:$V$2,0)), 0), IF(_xlpm.result=0, "", _xlpm.result) ) | F18: =_xlfn.LET( _xlpm.result, IFERROR(INDEX($C$3:$V$11, MATCH($A18,$A$3:$A$11,0), MATCH(F$14,$C$2:$V$2,0)), 0), IF(_xlpm.result=0, "", _xlpm.result) ) | G18: =_xlfn.LET( _xlpm.result, IFERROR(INDEX($C$3:$V$11, MATCH($A18,$A$3:$A$11,0), MATCH(G$14,$C$2:$V$2,0)), 0), IF(_xlpm.result=0, "", _xlpm.result) ) | H18: =IF(H$14="None","", 0 ) | I18: =IF(I$14="None","", 0 ) | J18: =IF(J$14="None","", 0 ) | K18: =IF(K$14="None","", 0 ) | L18: =IF(L$14="None","", 0 ) | M18: =IF(M$14="None","", 0 )
A19: RES Multiplier | B19: =SUM(C19:M19) -> 0 | C19: =_xlfn.LET( _xlpm.result, IFERROR(INDEX($C$3:$V$11, MATCH($A19,$A$3:$A$11,0), MATCH(C$14,$C$2:$V$2,0)), 0), IF(_xlpm.result=0, "", _xlpm.result) ) | D19: =_xlfn.LET( _xlpm.result, IFERROR(INDEX($C$3:$V$11, MATCH($A19,$A$3:$A$11,0), MATCH(D$14,$C$2:$V$2,0)), 0), IF(_xlpm.result=0, "", _xlpm.result) ) | E19: =_xlfn.LET( _xlpm.result, IFERROR(INDEX($C$3:$V$11, MATCH($A19,$A$3:$A$11,0), MATCH(E$14,$C$2:$V$2,0)), 0), IF(_xlpm.result=0, "", _xlpm.result) ) | F19: =_xlfn.LET( _xlpm.result, IFERROR(INDEX($C$3:$V$11, MATCH($A19,$A$3:$A$11,0), MATCH(F$14,$C$2:$V$2,0)), 0), IF(_xlpm.result=0, "", _xlpm.result) ) | G19: =_xlfn.LET( _xlpm.result, IFERROR(INDEX($C$3:$V$11, MATCH($A19,$A$3:$A$11,0), MATCH(G$14,$C$2:$V$2,0)), 0), IF(_xlpm.result=0, "", _xlpm.result) ) | H19: =IF(H$14="None","", 0 ) | I19: =IF(I$14="None","", 0 ) | J19: =IF(J$14="None","", 0 ) | K19: =IF(K$14="None","", 0 ) | L19: =IF(L$14="None","", 0 ) | M19: =IF(M$14="None","", 0 )
A20: Flat ATK | B20: =SUM(C20:M20) -> 0 | C20: =_xlfn.LET( _xlpm.result, IFERROR(INDEX($C$3:$V$11, MATCH($A20,$A$3:$A$11,0), MATCH(C$14,$C$2:$V$2,0)), 0), IF(_xlpm.result=0, "", _xlpm.result) ) | D20: =_xlfn.LET( _xlpm.result, IFERROR(INDEX($C$3:$V$11, MATCH($A20,$A$3:$A$11,0), MATCH(D$14,$C$2:$V$2,0)), 0), IF(_xlpm.result=0, "", _xlpm.result) ) | E20: =_xlfn.LET( _xlpm.result, IFERROR(INDEX($C$3:$V$11, MATCH($A20,$A$3:$A$11,0), MATCH(E$14,$C$2:$V$2,0)), 0), IF(_xlpm.result=0, "", _xlpm.result) ) | F20: =_xlfn.LET( _xlpm.result, IFERROR(INDEX($C$3:$V$11, MATCH($A20,$A$3:$A$11,0), MATCH(F$14,$C$2:$V$2,0)), 0), IF(_xlpm.result=0, "", _xlpm.result) ) | G20: =_xlfn.LET( _xlpm.result, IFERROR(INDEX($C$3:$V$11, MATCH($A20,$A$3:$A$11,0), MATCH(G$14,$C$2:$V$2,0)), 0), IF(_xlpm.result=0, "", _xlpm.result) ) | H20: =IF(H$14="None","", 0 ) | I20: =IF(I$14="None","", 0 ) | J20: =IF(J$14="None","", 0 ) | K20: =IF(K$14="None","", 0 ) | L20: =IF(L$14="None","", 0 ) | M20: =IF(M$14="None","", 0 )
A21: %ATK | B21: =SUM(C21:M21) -> 0.18 | C21: =_xlfn.LET( _xlpm.result, IFERROR(INDEX($C$3:$V$11, MATCH($A21,$A$3:$A$11,0), MATCH(C$14,$C$2:$V$2,0)), 0), IF(_xlpm.result=0, "", _xlpm.result) ) | D21: =_xlfn.LET( _xlpm.result, IFERROR(INDEX($C$3:$V$11, MATCH($A21,$A$3:$A$11,0), MATCH(D$14,$C$2:$V$2,0)), 0), IF(_xlpm.result=0, "", _xlpm.result) ) | E21: =_xlfn.LET( _xlpm.result, IFERROR(INDEX($C$3:$V$11, MATCH($A21,$A$3:$A$11,0), MATCH(E$14,$C$2:$V$2,0)), 0), IF(_xlpm.result=0, "", _xlpm.result) ) | F21: =_xlfn.LET( _xlpm.result, IFERROR(INDEX($C$3:$V$11, MATCH($A21,$A$3:$A$11,0), MATCH(F$14,$C$2:$V$2,0)), 0), IF(_xlpm.result=0, "", _xlpm.result) ) | G21: =_xlfn.LET( _xlpm.result, IFERROR(INDEX($C$3:$V$11, MATCH($A21,$A$3:$A$11,0), MATCH(G$14,$C$2:$V$2,0)), 0), IF(_xlpm.result=0, "", _xlpm.result) ) -> 0.18 | H21: =IF(H$14="None","", 28% ) | I21: =IF(I$14="None","", 28% ) | J21: =IF(J$14="None","", 0 ) | K21: =IF(K$14="None","", 20% ) | L21: =IF(L$14="None","", 24% ) | M21: =IF(M$14="None","", 41.3%+48% )
A22: %CRIT_DMG | B22: =SUM(C22:M22) -> 0 | C22: =_xlfn.LET( _xlpm.result, IFERROR(INDEX($C$3:$V$11, MATCH($A22,$A$3:$A$11,0), MATCH(C$14,$C$2:$V$2,0)), 0), IF(_xlpm.result=0, "", _xlpm.result) ) | D22: =_xlfn.LET( _xlpm.result, IFERROR(INDEX($C$3:$V$11, MATCH($A22,$A$3:$A$11,0), MATCH(D$14,$C$2:$V$2,0)), 0), IF(_xlpm.result=0, "", _xlpm.result) ) | E22: =_xlfn.LET( _xlpm.result, IFERROR(INDEX($C$3:$V$11, MATCH($A22,$A$3:$A$11,0), MATCH(E$14,$C$2:$V$2,0)), 0), IF(_xlpm.result=0, "", _xlpm.result) ) | F22: =_xlfn.LET( _xlpm.result, IFERROR(INDEX($C$3:$V$11, MATCH($A22,$A$3:$A$11,0), MATCH(F$14,$C$2:$V$2,0)), 0), IF(_xlpm.result=0, "", _xlpm.result) ) | G22: =_xlfn.LET( _xlpm.result, IFERROR(INDEX($C$3:$V$11, MATCH($A22,$A$3:$A$11,0), MATCH(G$14,$C$2:$V$2,0)), 0), IF(_xlpm.result=0, "", _xlpm.result) ) | H22: =IF(H$14="None","", 48% ) | I22: =IF(I$14="None","", 20% ) | J22: =IF(J$14="None","", 88.2% ) | K22: =IF(K$14="None","", 0 ) | L22: =IF(L$14="None","", 0 ) | M22: =IF(M$14="None","", 0 )
A23: EM | B23: =SUM(C23:N23) -> 0 | C23: =_xlfn.LET( _xlpm.result, IFERROR(INDEX($C$3:$V$11, MATCH($A23,$A$3:$A$11,0), MATCH(C$14,$C$2:$V$2,0)), 0), IF(_xlpm.result=0, "", _xlpm.result) ) | D23: =_xlfn.LET( _xlpm.result, IFERROR(INDEX($C$3:$V$11, MATCH($A23,$A$3:$A$11,0), MATCH(D$14,$C$2:$V$2,0)), 0), IF(_xlpm.result=0, "", _xlpm.result) ) | E23: =_xlfn.LET( _xlpm.result, IFERROR(INDEX($C$3:$V$11, MATCH($A23,$A$3:$A$11,0), MATCH(E$14,$C$2:$V$2,0)), 0), IF(_xlpm.result=0, "", _xlpm.result) ) | F23: =_xlfn.LET( _xlpm.result, IFERROR(INDEX($C$3:$V$11, MATCH($A23,$A$3:$A$11,0), MATCH(F$14,$C$2:$V$2,0)), 0), IF(_xlpm.result=0, "", _xlpm.result) ) | G23: =_xlfn.LET( _xlpm.result, IFERROR(INDEX($C$3:$V$11, MATCH($A23,$A$3:$A$11,0), MATCH(G$14,$C$2:$V$2,0)), 0), IF(_xlpm.result=0, "", _xlpm.result) ) | H23: =IF(H$14="None","", 0 ) | I23: =IF(I$14="None","", 0 ) | J23: =IF(J$14="None","", 0 ) | K23: =IF(K$14="None","", 0 ) | L23: =IF(L$14="None","", 96 ) | M23: =IF(M$14="None","", 0 )
A25: Sandrone Base Stats | B25: Total | C25: Base | D25: 1 | G25: =IFERROR(Interface!F5,"None") -> Please Choose a weapon
A26: Base ATK | B26: =SUM(C26:H26) -> 907.03 | C26: =VLOOKUP(Interface!$F$4,Information!$C$23:$E$38,3,FALSE) -> 342.03 | G26: =LOOKUP($G$25,Weapon!$D$3:$E$100) -> 565
A27: Base EM | B27: =SUM(C27:H27) -> 110 | C27: 0 | G27: =IF(G$25="None","", 110 ) -> 110
A28: Base CRIT DMG | B28: =SUM(C28:H28) -> 0.5 | C28: 0.5
A30: Sandrone Multiplier Stats | B30: Total | C30: 0 | D30: Talents | G30: Active Multiplier | H30: 5
A31: %ATK | B31: =SUM(C31:H31) -> 0.18 | G31: =$B$21 -> 0.18
A32: %EM | B32: =SUM(C32:H32) -> 0
A33: %CRIT DMG | B33: =SUM(C33:H33) -> 0
A35: Sandrone Additive Stats | B35: Total | C35: 0 | D35: Talents | G35: Active Multiplier | H35: 5
A36: Additive ATK | B36: =SUM(C36:H36) -> 0 | G36: =$B$20 -> 0
A37: Additive EM | B37: =SUM(C37:H37) -> 0 | G37: =$B$23 -> 0
A38: Additive CRIT DMG | B38: =SUM(D38:H38) -> 0 | G38: =$B$22 -> 0
A40: Sandrone Idle Stats | B40: Total
A41: ATK | B41: =B26*(1+F31)+B36 -> 907.03
A42: EM | B42: =B27+D37 -> 110
A43: CRIT DMG | B43: =B28 -> 0.5
A45: Sandrone Final Stats | B45: Total | C45: 0 | D45: 1 | E45: 2 | F45: 3 | G45: 4 | H45: 5
A46: Final ATK | B46: =(B26*(1+B31))+B36 -> 1070.2954
A47: Final EM | B47: =(B27*(1+B32))+B37 -> 110
...

Sheet artifact_substat_cases
A1: Sands_Main | B1: Goblet_Main | C1: Circlet_Main | D1: %ATK | E1: EM | F1: %CRIT_DMG | G1: Damage | I1: Return amount | J1: Top: 20 | K1: Sands_Main | L1: Goblet_Main | M1: Circlet_Main | N1: %ATK | O1: EM | P1: %CRIT_DMG | R1: Debug | S1: BaseATK | T1: BaseDamage | U1: FinalDamage | V1: Total_ATK_Buffs | W1: Total_ATK_Buffs_Artifacts | X1: Total_ATK_Buffs_Others | Y1: Total_CRIT_DMG_Buffs | Z1: Total_CRIT_DMG_Buffs_Artifacts | AA1: Total_CRIT_DMG_Buffs_Others | AB1: MainStats | AC1: ATK_Main | AD1: EM_Main | AE1: CRIT_DMG_Main | AF1: ATK_Sub | AG1: EM_Sub | AH1: CRIT_DMG_Sub | AI1: EM | AJ1: ATK | AK1: CRIT_DMG | AL1: BaseReactionCoefficient | AM1: Ability | AN1: BaseDMG_Multiplier | AO1: StellarReactionBase | AP1: Reaction_Bonus | AQ1: EM_Bonus | AR1: Reaction_AdditiveBaseDMGBonus | AS1: Elevation_Multiplier | AT1: RES_Multiplier
A2: %ATK | B2: %ATK | C2: %CRIT_DMG | D2: 8 | E2: 0 | F2: 22 | G2: =_xlfn.LET( _xlpm.BaseATK, Calculator!$B$26, _xlpm.MainStats, artifact_substat_cases[[#This Row],[Sands_Main]:[Circlet_Main]], _xlpm.ATK_Main,COUNTIF(_xlpm.MainStats,"%ATK")*46.6%, _xlpm.EM_Main,COUNTIF(_xlpm.MainStats,"EM")*186.5, _xlpm.CRIT_DMG_Main,COUNTIF(_xlpm.MainStats,"%CRIT_DMG")*62.2%, _xlpm.ATK_Sub,artifact_substat_cases[[#This Row],[%ATK]]*5.83%, _xlpm.EM_Sub,artifact_substat_cases[[#This Row],[EM]]*23.31, _xlpm.CRIT_DMG_Sub,artifact_substat_cases[[#This Row],[%CRIT_DMG]]*7.77%, _xlpm.EM,(Calculator!$B$47+ _xlpm.EM_Sub+_xlpm.EM_Main), _xlpm.ATK,(_xlpm.BaseATK*(1 +_xlpm.ATK_Sub+_xlpm.ATK_Main +Calculator!$B$31) +Calculator!$B$36), _xlpm.CRIT_DMG,(Calculator!$B$48+ _xlpm.CRIT_DMG_Sub+_xlpm.CRIT_DMG_Main), _xlpm.BaseReactionCoefficient, Calculator!$C$62, _xlpm.Ability,Calculator!$C$63, _xlpm.BaseDMG_Multiplier, Calculator!$C$65, _xlpm.StellarReactionBase,Calculator!$C$66 +MIN(_xlpm.ATK/100*0.7%,14%), _xlpm.Reaction_Bonus,Calculator!$C$68, _xlpm.EM_Bonus, (6/(1+2000/(_xlpm.EM+MIN(_xlpm.ATK/100*8,160)))), _xlpm.Reaction_AdditiveBaseDMGBonus,Calculator!$C$70, _xlpm.Elevation_Multiplier,Calculator!$C$72, _xlpm.RES_Multiplier, Calculator!$C$73, _xlpm.BaseDamage, PRODUCT( _xlpm.BaseReactionCoefficient, _xlpm.Ability, _xlpm.ATK, _xlpm.BaseDMG_Multiplier, (1 +_xlpm.StellarReactionBase), (1 +_xlpm.EM_Bonus + _xlpm.Reaction_Bonus) ) +_xlpm.Reaction_AdditiveBaseDMGBonus, _xlpm.FinalDamage,PRODUCT( _xlpm.BaseDamage, (1 +_xlpm.Elevation_Multiplier), _xlpm.RES_Multiplier, (1 +_xlpm.CRIT_DMG) ), _xlpm.FinalDamage ) -> 62764.447 | I2: Top: 5 | J2: {=_xlfn.LET( _xlpm.raw, $J$1, _xlpm.sorted, _xlfn._xlws.SORT($A$2:$G$10000,7,-1), _xlpm.n, IF(_xlpm.raw="All", ROWS(_xlpm.sorted), VALUE(TRIM(MID(_xlpm.raw,FIND(":",_xlpm.raw)+1,10)))), _xlpm.data, _xlfn.TAKE(_xlpm.sorted,_xlpm.n), _xlfn.CHOOSECOLS(_xlpm.data,7,1,2,3,4,5,6) )} -> 63385.325 | K2: %ATK | L2: %ATK | M2: %CRIT_DMG | N2: 9 | O2: 3 | P2: 18 | S2: {=_xlfn.LET( _xlpm.BaseATK, Calculator!$B$26, _xlpm.MainStats, $K2:$M2, _xlpm.ATK_Main,COUNTIF(_xlpm.MainStats,"%ATK")*46.6%, _xlpm.EM_Main,COUNTIF(_xlpm.MainStats,"EM")*186.5, _xlpm.CRIT_DMG_Main,COUNTIF(_xlpm.MainStats,"%CRIT_DMG")*62.2%, _xlpm.ATK_Sub,$N2*5.83%, _xlpm.EM_Sub,$O2*23.31, _xlpm.CRIT_DMG_Sub,$P2*7.77%, _xlpm.Total_ATK_Buffs_Others, Calculator!$B$31, _xlpm.Total_CRIT_DMG_Buffs_Others, Calculator!$B$48, _xlpm.Total_ATK_Buffs_Artifacts, _xlpm.ATK_Sub+_xlpm.ATK_Main, _xlpm.Total_CRIT_DMG_Buffs_Artifacts, _xlpm.CRIT_DMG_Sub+_xlpm.CRIT_DMG_Main, _xlpm.Total_ATK_Buffs, (_xlpm.Total_ATK_Buffs_Artifacts + _xlpm.Total_ATK_Buffs_Others), _xlpm.Total_CRIT_DMG_Buffs, (_xlpm.Total_CRIT_DMG_Buffs_Artifacts + _xlpm.Total_CRIT_DMG_Buffs_Others), _xlpm.EM,(Calculator!$B$47+ _xlpm.EM_Sub+_xlpm.EM_Main), _xlpm.ATK,(_xlpm.BaseATK*(1 +_xlpm.Total_ATK_Buffs) +Calculator!$B$36), _xlpm.CRIT_DMG,(_xlpm.Total_CRIT_DMG_Buffs), _xlpm.BaseReactionCoefficient, Calculator!$C$62, _xlpm.Ability,Calculator!$C$63, _xlpm.BaseDMG_Multiplier, Calculator!$C$65, _xlpm.StellarReactionBase,Calculator!$C$66 +MIN(_xlpm.ATK/100*0.7%,14%), _xlpm.Reaction_Bonus,Calculator!$C$68, _xlpm.EM_Bonus, (6/(1+2000/(_xlpm.EM+MIN(_xlpm.ATK/100*8,160)))), _xlpm.Reaction_AdditiveBaseDMGBonus,Calculator!$C$70, _xlpm.Elevation_Multiplier,Calculator!$C$72, _xlpm.RES_Multiplier, Calculator!$C$73, _xlpm.BaseDamage, PRODUCT( _xlpm.BaseReactionCoefficient, _xlpm.Ability, _xlpm.ATK, _xlpm.BaseDMG_Multiplier, (1+_xlpm.StellarReactionBase), (1+_xlpm.EM_Bonus+_xlpm.Reaction_Bonus) )+_xlpm.Reaction_AdditiveBaseDMGBonus, _xlpm.FinalDamage, PRODUCT( _xlpm.BaseDamage, (1+_xlpm.Elevation_Multiplier), _xlpm.RES_Multiplier, (1+_xlpm.CRIT_DMG) ), TRANSPOSE(_xlfn.VSTACK( _xlpm.BaseATK, _xlpm.BaseDamage, _xlpm.FinalDamage, _xlpm.Total_ATK_Buffs, _xlpm.Total_ATK_Buffs_Artifacts, _xlpm.Total_ATK_Buffs_Others, _xlpm.Total_CRIT_DMG_Buffs, _xlpm.Total_CRIT_DMG_Buffs_Artifacts, _xlpm.Total_CRIT_DMG_Buffs_Others, _xlfn.TEXTJOIN(", ",TRUE,_xlpm.MainStats), _xlpm.ATK_Main, _xlpm.EM_Main, _xlpm.CRIT_DMG_Main, _xlpm.ATK_Sub, _xlpm.EM_Sub, _xlpm.CRIT_DMG_Sub, _xlpm.EM, _xlpm.ATK, _xlpm.CRIT_DMG, _xlpm.BaseReactionCoefficient, _xlpm.Ability, _xlpm.BaseDMG_Multiplier, _xlpm.StellarReactionBase, _xlpm.Reaction_Bonus, _xlpm.EM_Bonus, _xlpm.Reaction_AdditiveBaseDMGBonus, _xlpm.Elevation_Multiplier, _xlpm.RES_Multiplier ) ))} -> 907.03 | T2: 20004.584 | U2: 63385.325 | V2: 1.6367 | W2: 1.4567 | X2: 0.18 | Y2: 2.5206 | Z2: 2.0206 | AA2: 0.5 | AB2: %ATK, %ATK, %CRIT_DMG | AC2: 0.932 | AD2: 0 | AE2: 0.622 | AF2: 0.5247 | AG2: 69.93 | AH2: 1.3986 | AI2: 179.93 | AJ2: 2391.566 | AK2: 2.5206 | AL2: 2 | AM2: 1.615 | AN2: 1 | AO2: 0.14 | AP2: 0.4 | AQ2: 0.87164146 | AR2: 0 | AS2: 0 | AT2: 0.9
A3: %ATK | B3: %ATK | C3: %CRIT_DMG | D3: 7 | E3: 0 | F3: 23 | G3: =_xlfn.LET( _xlpm.BaseATK, Calculator!$B$26, _xlpm.MainStats, artifact_substat_cases[[#This Row],[Sands_Main]:[Circlet_Main]], _xlpm.ATK_Main,COUNTIF(_xlpm.MainStats,"%ATK")*46.6%, _xlpm.EM_Main,COUNTIF(_xlpm.MainStats,"EM")*186.5, _xlpm.CRIT_DMG_Main,COUNTIF(_xlpm.MainStats,"%CRIT_DMG")*62.2%, _xlpm.ATK_Sub,artifact_substat_cases[[#This Row],[%ATK]]*5.83%, _xlpm.EM_Sub,artifact_substat_cases[[#This Row],[EM]]*23.31, _xlpm.CRIT_DMG_Sub,artifact_substat_cases[[#This Row],[%CRIT_DMG]]*7.77%, _xlpm.EM,(Calculator!$B$47+ _xlpm.EM_Sub+_xlpm.EM_Main), _xlpm.ATK,(_xlpm.BaseATK*(1 +_xlpm.ATK_Sub+_xlpm.ATK_Main +Calculator!$B$31) +Calculator!$B$36), _xlpm.CRIT_DMG,(Calculator!$B$48+ _xlpm.CRIT_DMG_Sub+_xlpm.CRIT_DMG_Main), _xlpm.BaseReactionCoefficient, Calculator!$C$62, _xlpm.Ability,Calculator!$C$63, _xlpm.BaseDMG_Multiplier, Calculator!$C$65, _xlpm.StellarReactionBase,Calculator!$C$66 +MIN(_xlpm.ATK/100*0.7%,14%), _xlpm.Reaction_Bonus,Calculator!$C$68, _xlpm.EM_Bonus, (6/(1+2000/(_xlpm.EM+MIN(_xlpm.ATK/100*8,160)))), _xlpm.Reaction_AdditiveBaseDMGBonus,Calculator!$C$70, _xlpm.Elevation_Multiplier,Calculator!$C$72, _xlpm.RES_Multiplier, Calculator!$C$73, _xlpm.BaseDamage, PRODUCT( _xlpm.BaseReactionCoefficient, _xlpm.Ability, _xlpm.ATK, _xlpm.BaseDMG_Multiplier, (1 +_xlpm.StellarReactionBase), (1 +_xlpm.EM_Bonus + _xlpm.Reaction_Bonus) ) +_xlpm.Reaction_AdditiveBaseDMGBonus, _xlpm.FinalDamage,PRODUCT( _xlpm.BaseDamage, (1 +_xlpm.Elevation_Multiplier), _xlpm.RES_Multiplier, (1 +_xlpm.CRIT_DMG) ), _xlpm.FinalDamage ) -> 62589.355 | I3: Top: 10 | J3: 63366.692 | K3: %ATK | L3: %ATK | M3: %CRIT_DMG | N3: 9 | O3: 4 | P3: 17 | S3: {=_xlfn.LET( _xlpm.BaseATK, Calculator!$B$26, _xlpm.MainStats, $K3:$M3, _xlpm.ATK_Main,COUNTIF(_xlpm.MainStats,"%ATK")*46.6%, _xlpm.EM_Main,COUNTIF(_xlpm.MainStats,"EM")*186.5, _xlpm.CRIT_DMG_Main,COUNTIF(_xlpm.MainStats,"%CRIT_DMG")*62.2%, _xlpm.ATK_Sub,$N3*5.83%, _xlpm.EM_Sub,$O3*23.31, _xlpm.CRIT_DMG_Sub,$P3*7.77%, _xlpm.Total_ATK_Buffs_Others, Calculator!$B$31, _xlpm.Total_CRIT_DMG_Buffs_Others, Calculator!$B$48, _xlpm.Total_ATK_Buffs_Artifacts, _xlpm.ATK_Sub+_xlpm.ATK_Main, _xlpm.Total_CRIT_DMG_Buffs_Artifacts, _xlpm.CRIT_DMG_Sub+_xlpm.CRIT_DMG_Main, _xlpm.Total_ATK_Buffs, (_xlpm.Total_ATK_Buffs_Artifacts + _xlpm.Total_ATK_Buffs_Others), _xlpm.Total_CRIT_DMG_Buffs, (_xlpm.Total_CRIT_DMG_Buffs_Artifacts + _xlpm.Total_CRIT_DMG_Buffs_Others), _xlpm.EM,(Calculator!$B$47+ _xlpm.EM_Sub+_xlpm.EM_Main), _xlpm.ATK,(_xlpm.BaseATK*(1 +_xlpm.Total_ATK_Buffs) +Calculator!$B$36), _xlpm.CRIT_DMG,(_xlpm.Total_CRIT_DMG_Buffs), _xlpm.BaseReactionCoefficient, Calculator!$C$62, _xlpm.Ability,Calculator!$C$63, _xlpm.BaseDMG_Multiplier, Calculator!$C$65, _xlpm.StellarReactionBase,Calculator!$C$66 +MIN(_xlpm.ATK/100*0.7%,14%), _xlpm.Reaction_Bonus,Calculator!$C$68, _xlpm.EM_Bonus, (6/(1+2000/(_xlpm.EM+MIN(_xlpm.ATK/100*8,160)))), _xlpm.Reaction_AdditiveBaseDMGBonus,Calculator!$C$70, _xlpm.Elevation_Multiplier,Calculator!$C$72, _xlpm.RES_Multiplier, Calculator!$C$73, _xlpm.BaseDamage, PRODUCT( _xlpm.BaseReactionCoefficient, _xlpm.Ability, _xlpm.ATK, _xlpm.BaseDMG_Multiplier, (1+_xlpm.StellarReactionBase), (1+_xlpm.EM_Bonus+_xlpm.Reaction_Bonus) )+_xlpm.Reaction_AdditiveBaseDMGBonus, _xlpm.FinalDamage, PRODUCT( _xlpm.BaseDamage, (1+_xlpm.Elevation_Multiplier), _xlpm.RES_Multiplier, (1+_xlpm.CRIT_DMG) ), TRANSPOSE(_xlfn.VSTACK( _xlpm.BaseATK, _xlpm.BaseDamage, _xlpm.FinalDamage, _xlpm.Total_ATK_Buffs, _xlpm.Total_ATK_Buffs_Artifacts, _xlpm.Total_ATK_Buffs_Others, _xlpm.Total_CRIT_DMG_Buffs, _xlpm.Total_CRIT_DMG_Buffs_Artifacts, _xlpm.Total_CRIT_DMG_Buffs_Others, _xlfn.TEXTJOIN(", ",TRUE,_xlpm.MainStats), _xlpm.ATK_Main, _xlpm.EM_Main, _xlpm.CRIT_DMG_Main, _xlpm.ATK_Sub, _xlpm.EM_Sub, _xlpm.CRIT_DMG_Sub, _xlpm.EM, _xlpm.ATK, _xlpm.CRIT_DMG, _xlpm.BaseReactionCoefficient, _xlpm.Ability, _xlpm.BaseDMG_Multiplier, _xlpm.StellarReactionBase, _xlpm.Reaction_Bonus, _xlpm.EM_Bonus, _xlpm.Reaction_AdditiveBaseDMGBonus, _xlpm.Elevation_Multiplier, _xlpm.RES_Multiplier ) ))} -> 907.03 | T3: 20450.038 | U3: 63366.692 | V3: 1.6367 | W3: 1.4567 | X3: 0.18 | Y3: 2.4429 | Z3: 1.9429 | AA3: 0.5 | AB3: %ATK, %ATK, %CRIT_DMG | AC3: 0.932 | AD3: 0 | AE3: 0.622 | AF3: 0.5247 | AG3: 93.24 | AH3: 1.3209 | AI3: 203.24 | AJ3: 2391.566 | AK3: 2.4429 | AL3: 2 | AM3: 1.615 | AN3: 1 | AO3: 0.14 | AP3: 0.4 | AQ3: 0.92222542 | AR3: 0 | AS3: 0 | AT3: 0.9
A4: %ATK | B4: %ATK | C4: %CRIT_DMG | D4: 9 | E4: 0 | F4: 21 | G4: =_xlfn.LET( _xlpm.BaseATK, Calculator!$B$26, _xlpm.MainStats, artifact_substat_cases[[#This Row],[Sands_Main]:[Circlet_Main]], _xlpm.ATK_Main,COUNTIF(_xlpm.MainStats,"%ATK")*46.6%, _xlpm.EM_Main,COUNTIF(_xlpm.MainStats,"EM")*186.5, _xlpm.CRIT_DMG_Main,COUNTIF(_xlpm.MainStats,"%CRIT_DMG")*62.2%, _xlpm.ATK_Sub,artifact_substat_cases[[#This Row],[%ATK]]*5.83%, _xlpm.EM_Sub,artifact_substat_cases[[#This Row],[EM]]*23.31, _xlpm.CRIT_DMG_Sub,artifact_substat_cases[[#This Row],[%CRIT_DMG]]*7.77%, _xlpm.EM,(Calculator!$B$47+ _xlpm.EM_Sub+_xlpm.EM_Main), _xlpm.ATK,(_xlpm.BaseATK*(1 +_xlpm.ATK_Sub+_xlpm.ATK_Main +Calculator!$B$31) +Calculator!$B$36), _xlpm.CRIT_DMG,(Calculator!$B$48+ _xlpm.CRIT_DMG_Sub+_xlpm.CRIT_DMG_Main), _xlpm.BaseReactionCoefficient, Calculator!$C$62, _xlpm.Ability,Calculator!$C$63, _xlpm.BaseDMG_Multiplier, Calculator!$C$65, _xlpm.StellarReactionBase,Calculator!$C$66 +MIN(_xlpm.ATK/100*0.7%,14%), _xlpm.Reaction_Bonus,Calculator!$C$68, _xlpm.EM_Bonus, (6/(1+2000/(_xlpm.EM+MIN(_xlpm.ATK/100*8,160)))), _xlpm.Reaction_AdditiveBaseDMGBonus,Calculator!$C$70, _xlpm.Elevation_Multiplier,Calculator!$C$72, _xlpm.RES_Multiplier, Calculator!$C$73, _xlpm.BaseDamage, PRODUCT( _xlpm.BaseReactionCoefficient, _xlpm.Ability, _xlpm.ATK, _xlpm.BaseDMG_Multiplier, (1 +_xlpm.StellarReactionBase), (1 +_xlpm.EM_Bonus + _xlpm.Reaction_Bonus) ) +_xlpm.Reaction_AdditiveBaseDMGBonus, _xlpm.FinalDamage,PRODUCT( _xlpm.BaseDamage, (1 +_xlpm.Elevation_Multiplier), _xlpm.RES_Multiplier, (1 +_xlpm.CRIT_DMG) ), _xlpm.FinalDamage ) -> 62881.979 | I4: Top: 20 | J4: 63364.044 | K4: %ATK | L4: %ATK | M4: %CRIT_DMG | N4: 8 | O4: 4 | P4: 18 | S4: {=_xlfn.LET( _xlpm.BaseATK, Calculator!$B$26, _xlpm.MainStats, $K4:$M4, _xlpm.ATK_Main,COUNTIF(_xlpm.MainStats,"%ATK")*46.6%, _xlpm.EM_Main,COUNTIF(_xlpm.MainStats,"EM")*186.5, _xlpm.CRIT_DMG_Main,COUNTIF(_xlpm.MainStats,"%CRIT_DMG")*62.2%, _xlpm.ATK_Sub,$N4*5.83%, _xlpm.EM_Sub,$O4*23.31, _xlpm.CRIT_DMG_Sub,$P4*7.77%, _xlpm.Total_ATK_Buffs_Others, Calculator!$B$31, _xlpm.Total_CRIT_DMG_Buffs_Others, Calculator!$B$48, _xlpm.Total_ATK_Buffs_Artifacts, _xlpm.ATK_Sub+_xlpm.ATK_Main, _xlpm.Total_CRIT_DMG_Buffs_Artifacts, _xlpm.CRIT_DMG_Sub+_xlpm.CRIT_DMG_Main, _xlpm.Total_ATK_Buffs, (_xlpm.Total_ATK_Buffs_Artifacts + _xlpm.Total_ATK_Buffs_Others), _xlpm.Total_CRIT_DMG_Buffs, (_xlpm.Total_CRIT_DMG_Buffs_Artifacts + _xlpm.Total_CRIT_DMG_Buffs_Others), _xlpm.EM,(Calculator!$B$47+ _xlpm.EM_Sub+_xlpm.EM_Main), _xlpm.ATK,(_xlpm.BaseATK*(1 +_xlpm.Total_ATK_Buffs) +Calculator!$B$36), _xlpm.CRIT_DMG,(_xlpm.Total_CRIT_DMG_Buffs), _xlpm.BaseReactionCoefficient, Calculator!$C$62, _xlpm.Ability,Calculator!$C$63, _xlpm.BaseDMG_Multiplier, Calculator!$C$65, _xlpm.StellarReactionBase,Calculator!$C$66 +MIN(_xlpm.ATK/100*0.7%,14%), _xlpm.Reaction_Bonus,Calculator!$C$68, _xlpm.EM_Bonus, (6/(1+2000/(_xlpm.EM+MIN(_xlpm.ATK/100*8,160)))), _xlpm.Reaction_AdditiveBaseDMGBonus,Calculator!$C$70, _xlpm.Elevation_Multiplier,Calculator!$C$72, _xlpm.RES_Multiplier, Calculator!$C$73, _xlpm.BaseDamage, PRODUCT( _xlpm.BaseReactionCoefficient, _xlpm.Ability, _xlpm.ATK, _xlpm.BaseDMG_Multiplier, (1+_xlpm.StellarReactionBase), (1+_xlpm.EM_Bonus+_xlpm.Reaction_Bonus) )+_xlpm.Reaction_AdditiveBaseDMGBonus, _xlpm.FinalDamage, PRODUCT( _xlpm.BaseDamage, (1+_xlpm.Elevation_Multiplier), _xlpm.RES_Multiplier, (1+_xlpm.CRIT_DMG) ), TRANSPOSE(_xlfn.VSTACK( _xlpm.BaseATK, _xlpm.BaseDamage, _xlpm.FinalDamage, _xlpm.Total_ATK_Buffs, _xlpm.Total_ATK_Buffs_Artifacts, _xlpm.Total_ATK_Buffs_Others, _xlpm.Total_CRIT_DMG_Buffs, _xlpm.Total_CRIT_DMG_Buffs_Artifacts, _xlpm.Total_CRIT_DMG_Buffs_Others, _xlfn.TEXTJOIN(", ",TRUE,_xlpm.MainStats), _xlpm.ATK_Main, _xlpm.EM_Main, _xlpm.CRIT_DMG_Main, _xlpm.ATK_Sub, _xlpm.EM_Sub, _xlpm.CRIT_DMG_Sub, _xlpm.EM, _xlpm.ATK, _xlpm.CRIT_DMG, _xlpm.BaseReactionCoefficient, _xlpm.Ability, _xlpm.BaseDMG_Multiplier, _xlpm.StellarReactionBase, _xlpm.Reaction_Bonus, _xlpm.EM_Bonus, _xlpm.Reaction_AdditiveBaseDMGBonus, _xlpm.Elevation_Multiplier, _xlpm.RES_Multiplier ) ))} -> 907.03 | T4: 19997.868 | U4: 63364.044 | V4: 1.5784 | W4: 1.3984 | X4: 0.18 | Y4: 2.5206 | Z4: 2.0206 | AA4: 0.5 | AB4: %ATK, %ATK, %CRIT_DMG | AC4: 0.932 | AD4: 0 | AE4: 0.622 | AF4: 0.4664 | AG4: 93.24 | AH4: 1.3986 | AI4: 203.24 | AJ4: 2338.6862 | AK4: 2.5206 | AL4: 2 | AM4: 1.615 | AN4: 1 | AO4: 0.14 | AP4: 0.4 | AQ4: 0.92222542 | AR4: 0 | AS4: 0 | AT4: 0.9
A5: %ATK | B5: %ATK | C5: %CRIT_DMG | D5: 6 | E5: 0 | F5: 24 | G5: =_xlfn.LET( _xlpm.BaseATK, Calculator!$B$26, _xlpm.MainStats, artifact_substat_cases[[#This Row],[Sands_Main]:[Circlet_Main]], _xlpm.ATK_Main,COUNTIF(_xlpm.MainStats,"%ATK")*46.6%, _xlpm.EM_Main,COUNTIF(_xlpm.MainStats,"EM")*186.5, _xlpm.CRIT_DMG_Main,COUNTIF(_xlpm.MainStats,"%CRIT_DMG")*62.2%, _xlpm.ATK_Sub,artifact_substat_cases[[#This Row],[%ATK]]*5.83%, _xlpm.EM_Sub,artifact_substat_cases[[#This Row],[EM]]*23.31, _xlpm.CRIT_DMG_Sub,artifact_substat_cases[[#This Row],[%CRIT_DMG]]*7.77%, _xlpm.EM,(Calculator!$B$47+ _xlpm.EM_Sub+_xlpm.EM_Main), _xlpm.ATK,(_xlpm.BaseATK*(1 +_xlpm.ATK_Sub+_xlpm.ATK_Main +Calculator!$B$31) +Calculator!$B$36), _xlpm.CRIT_DMG,(Calculator!$B$48+ _xlpm.CRIT_DMG_Sub+_xlpm.CRIT_DMG_Main), _xlpm.BaseReactionCoefficient, Calculator!$C$62, _xlpm.Ability,Calculator!$C$63, _xlpm.BaseDMG_Multiplier, Calculator!$C$65, _xlpm.StellarReactionBase,Calculator!$C$66 +MIN(_xlpm.ATK/100*0.7%,14%), _xlpm.Reaction_Bonus,Calculator!$C$68, _xlpm.EM_Bonus, (6/(1+2000/(_xlpm.EM+MIN(_xlpm.ATK/100*8,160)))), _xlpm.Reaction_AdditiveBaseDMGBonus,Calculator!$C$70, _xlpm.Elevation_Multiplier,Calculator!$C$72, _xlpm.RES_Multiplier, Calculator!$C$73, _xlpm.BaseDamage, PRODUCT( _xlpm.BaseReactionCoefficient, _xlpm.Ability, _xlpm.ATK, _xlpm.BaseDMG_Multiplier, (1 +_xlpm.StellarReactionBase), (1 +_xlpm.EM_Bonus + _xlpm.Reaction_Bonus) ) +_xlpm.Reaction_AdditiveBaseDMGBonus, _xlpm.FinalDamage,PRODUCT( _xlpm.BaseDamage, (1 +_xlpm.Elevation_Multiplier), _xlpm.RES_Multiplier, (1 +_xlpm.CRIT_DMG) ), _xlpm.FinalDamage ) -> 62356.702 | I5: Top: 50 | J5: 63356.985 | K5: %ATK | L5: %ATK | M5: %CRIT_DMG | N5: 10 | O5: 3 | P5: 17 | S5: {=_xlfn.LET( _xlpm.BaseATK, Calculator!$B$26, _xlpm.MainStats, $K5:$M5, _xlpm.ATK_Main,COUNTIF(_xlpm.MainStats,"%ATK")*46.6%, _xlpm.EM_Main,COUNTIF(_xlpm.MainStats,"EM")*186.5, _xlpm.CRIT_DMG_Main,COUNTIF(_xlpm.MainStats,"%CRIT_DMG")*62.2%, _xlpm.ATK_Sub,$N5*5.83%, _xlpm.EM_Sub,$O5*23.31, _xlpm.CRIT_DMG_Sub,$P5*7.77%, _xlpm.Total_ATK_Buffs_Others, Calculator!$B$31, _xlpm.Total_CRIT_DMG_Buffs_Others, Calculator!$B$48, _xlpm.Total_ATK_Buffs_Artifacts, _xlpm.ATK_Sub+_xlpm.ATK_Main, _xlpm.Total_CRIT_DMG_Buffs_Artifacts, _xlpm.CRIT_DMG_Sub+_xlpm.CRIT_DMG_Main, _xlpm.Total_ATK_Buffs, (_xlpm.Total_ATK_Buffs_Artifacts + _xlpm.Total_ATK_Buffs_Others), _xlpm.Total_CRIT_DMG_Buffs, (_xlpm.Total_CRIT_DMG_Buffs_Artifacts + _xlpm.Total_CRIT_DMG_Buffs_Others), _xlpm.EM,(Calculator!$B$47+ _xlpm.EM_Sub+_xlpm.EM_Main), _xlpm.ATK,(_xlpm.BaseATK*(1 +_xlpm.Total_ATK_Buffs) +Calculator!$B$36), _xlpm.CRIT_DMG,(_xlpm.Total_CRIT_DMG_Buffs), _xlpm.BaseReactionCoefficient, Calculator!$C$62, _xlpm.Ability,Calculator!$C$63, _xlpm.BaseDMG_Multiplier, Calculator!$C$65, _xlpm.StellarReactionBase,Calculator!$C$66 +MIN(_xlpm.ATK/100*0.7%,14%), _xlpm.Reaction_Bonus,Calculator!$C$68, _xlpm.EM_Bonus, (6/(1+2000/(_xlpm.EM+MIN(_xlpm.ATK/100*8,160)))), _xlpm.Reaction_AdditiveBaseDMGBonus,Calculator!$C$70, _xlpm.Elevation_Multiplier,Calculator!$C$72, _xlpm.RES_Multiplier, Calculator!$C$73, _xlpm.BaseDamage, PRODUCT( _xlpm.BaseReactionCoefficient, _xlpm.Ability, _xlpm.ATK, _xlpm.BaseDMG_Multiplier, (1+_xlpm.StellarReactionBase), (1+_xlpm.EM_Bonus+_xlpm.Reaction_Bonus) )+_xlpm.Reaction_AdditiveBaseDMGBonus, _xlpm.FinalDamage, PRODUCT( _xlpm.BaseDamage, (1+_xlpm.Elevation_Multiplier), _xlpm.RES_Multiplier, (1+_xlpm.CRIT_DMG) ), TRANSPOSE(_xlfn.VSTACK( _xlpm.BaseATK, _xlpm.BaseDamage, _xlpm.FinalDamage, _xlpm.Total_ATK_Buffs, _xlpm.Total_ATK_Buffs_Artifacts, _xlpm.Total_ATK_Buffs_Others, _xlpm.Total_CRIT_DMG_Buffs, _xlpm.Total_CRIT_DMG_Buffs_Artifacts, _xlpm.Total_CRIT_DMG_Buffs_Others, _xlfn.TEXTJOIN(", ",TRUE,_xlpm.MainStats), _xlpm.ATK_Main, _xlpm.EM_Main, _xlpm.CRIT_DMG_Main, _xlpm.ATK_Sub, _xlpm.EM_Sub, _xlpm.CRIT_DMG_Sub, _xlpm.EM, _xlpm.ATK, _xlpm.CRIT_DMG, _xlpm.BaseReactionCoefficient, _xlpm.Ability, _xlpm.BaseDMG_Multiplier, _xlpm.StellarReactionBase, _xlpm.Reaction_Bonus, _xlpm.EM_Bonus, _xlpm.Reaction_AdditiveBaseDMGBonus, _xlpm.Elevation_Multiplier, _xlpm.RES_Multiplier ) ))} -> 907.03 | T5: 20446.905 | U5: 63356.985 | V5: 1.695 | W5: 1.515 | X5: 0.18 | Y5: 2.4429 | Z5: 1.9429 | AA5: 0.5 | AB5: %ATK, %ATK, %CRIT_DMG | AC5: 0.932 | AD5: 0 | AE5: 0.622 | AF5: 0.583 | AG5: 69.93 | AH5: 1.3209 | AI5: 179.93 | AJ5: 2444.4459 | AK5: 2.4429 | AL5: 2 | AM5: 1.615 | AN5: 1 | AO5: 0.14 | AP5: 0.4 | AQ5: 0.87164146 | AR5: 0 | AS5: 0 | AT5: 0.9
A6: %ATK | B6: %ATK | C6: %CRIT_DMG | D6: 10 | E6: 0 | F6: 20 | G6: =_xlfn.LET( _xlpm.BaseATK, Calculator!$B$26, _xlpm.MainStats, artifact_substat_cases[[#This Row],[Sands_Main]:[Circlet_Main]], _xlpm.ATK_Main,COUNTIF(_xlpm.MainStats,"%ATK")*46.6%, _xlpm.EM_Main,COUNTIF(_xlpm.MainStats,"EM")*186.5, _xlpm.CRIT_DMG_Main,COUNTIF(_xlpm.MainStats,"%CRIT_DMG")*62.2%, _xlpm.ATK_Sub,artifact_substat_cases[[#This Row],[%ATK]]*5.83%, _xlpm.EM_Sub,artifact_substat_cases[[#This Row],[EM]]*23.31, _xlpm.CRIT_DMG_Sub,artifact_substat_cases[[#This Row],[%CRIT_DMG]]*7.77%, _xlpm.EM,(Calculator!$B$47+ _xlpm.EM_Sub+_xlpm.EM_Main), _xlpm.ATK,(_xlpm.BaseATK*(1 +_xlpm.ATK_Sub+_xlpm.ATK_Main +Calculator!$B$31) +Calculator!$B$36), _xlpm.CRIT_DMG,(Calculator!$B$48+ _xlpm.CRIT_DMG_Sub+_xlpm.CRIT_DMG_Main), _xlpm.BaseReactionCoefficient, Calculator!$C$62, _xlpm.Ability,Calculator!$C$63, _xlpm.BaseDMG_Multiplier, Calculator!$C$65, _xlpm.StellarReactionBase,Calculator!$C$66 +MIN(_xlpm.ATK/100*0.7%,14%), _xlpm.Reaction_Bonus,Calculator!$C$68, _xlpm.EM_Bonus, (6/(1+2000/(_xlpm.EM+MIN(_xlpm.ATK/100*8,160)))), _xlpm.Reaction_AdditiveBaseDMGBonus,Calculator!$C$70, _xlpm.Elevation_Multiplier,Calculator!$C$72, _xlpm.RES_Multiplier, Calculator!$C$73, _xlpm.BaseDamage, PRODUCT( _xlpm.BaseReactionCoefficient, _xlpm.Ability, _xlpm.ATK, _xlpm.BaseDMG_Multiplier, (1 +_xlpm.StellarReactionBase), (1 +_xlpm.EM_Bonus + _xlpm.Reaction_Bonus) ) +_xlpm.Reaction_AdditiveBaseDMGBonus, _xlpm.FinalDamage,PRODUCT( _xlpm.BaseDamage, (1 +_xlpm.Elevation_Multiplier), _xlpm.RES_Multiplier, (1 +_xlpm.CRIT_DMG) ), _xlpm.FinalDamage ) -> 62941.95 | I6: Top: 100 | J6: 63351.803 | K6: %ATK | L6: %ATK | M6: %CRIT_DMG | N6: 8 | O6: 3 | P6: 19 | S6: {=_xlfn.LET( _xlpm.BaseATK, Calculator!$B$26, _xlpm.MainStats, $K6:$M6, _xlpm.ATK_Main,COUNTIF(_xlpm.MainStats,"%ATK")*46.6%, _xlpm.EM_Main,COUNTIF(_xlpm.MainStats,"EM")*186.5, _xlpm.CRIT_DMG_Main,COUNTIF(_xlpm.MainStats,"%CRIT_DMG")*62.2%, _xlpm.ATK_Sub,$N6*5.83%, _xlpm.EM_Sub,$O6*23.31, _xlpm.CRIT_DMG_Sub,$P6*7.77%, _xlpm.Total_ATK_Buffs_Others, Calculator!$B$31, _xlpm.Total_CRIT_DMG_Buffs_Others, Calculator!$B$48, _xlpm.Total_ATK_Buffs_Artifacts, _xlpm.ATK_Sub+_xlpm.ATK_Main, _xlpm.Total_CRIT_DMG_Buffs_Artifacts, _xlpm.CRIT_DMG_Sub+_xlpm.CRIT_DMG_Main, _xlpm.Total_ATK_Buffs, (_xlpm.Total_ATK_Buffs_Artifacts + _xlpm.Total_ATK_Buffs_Others), _xlpm.Total_CRIT_DMG_Buffs, (_xlpm.Total_CRIT_DMG_Buffs_Artifacts + _xlpm.Total_CRIT_DMG_Buffs_Others), _xlpm.EM,(Calculator!$B$47+ _xlpm.EM_Sub+_xlpm.EM_Main), _xlpm.ATK,(_xlpm.BaseATK*(1 +_xlpm.Total_ATK_Buffs) +Calculator!$B$36), _xlpm.CRIT_DMG,(_xlpm.Total_CRIT_DMG_Buffs), _xlpm.BaseReactionCoefficient, Calculator!$C$62, _xlpm.Ability,Calculator!$C$63, _xlpm.BaseDMG_Multiplier, Calculator!$C$65, _xlpm.StellarReactionBase,Calculator!$C$66 +MIN(_xlpm.ATK/100*0.7%,14%), _xlpm.Reaction_Bonus,Calculator!$C$68, _xlpm.EM_Bonus, (6/(1+2000/(_xlpm.EM+MIN(_xlpm.ATK/100*8,160)))), _xlpm.Reaction_AdditiveBaseDMGBonus,Calculator!$C$70, _xlpm.Elevation_Multiplier,Calculator!$C$72, _xlpm.RES_Multiplier, Calculator!$C$73, _xlpm.BaseDamage, PRODUCT( _xlpm.BaseReactionCoefficient, _xlpm.Ability, _xlpm.ATK, _xlpm.BaseDMG_Multiplier, (1+_xlpm.StellarReactionBase), (1+_xlpm.EM_Bonus+_xlpm.Reaction_Bonus) )+_xlpm.Reaction_AdditiveBaseDMGBonus, _xlpm.FinalDamage, PRODUCT( _xlpm.BaseDamage, (1+_xlpm.Elevation_Multiplier), _xlpm.RES_Multiplier, (1+_xlpm.CRIT_DMG) ), TRANSPOSE(_xlfn.VSTACK( _xlpm.BaseATK, _xlpm.BaseDamage, _xlpm.FinalDamage, _xlpm.Total_ATK_Buffs, _xlpm.Total_ATK_Buffs_Artifacts, _xlpm.Total_ATK_Buffs_Others, _xlpm.Total_CRIT_DMG_Buffs, _xlpm.Total_CRIT_DMG_Buffs_Artifacts, _xlpm.Total_CRIT_DMG_Buffs_Others, _xlfn.TEXTJOIN(", ",TRUE,_xlpm.MainStats), _xlpm.ATK_Main, _xlpm.EM_Main, _xlpm.CRIT_DMG_Main, _xlpm.ATK_Sub, _xlpm.EM_Sub, _xlpm.CRIT_DMG_Sub, _xlpm.EM, _xlpm.ATK, _xlpm.CRIT_DMG, _xlpm.BaseReactionCoefficient, _xlpm.Ability, _xlpm.BaseDMG_Multiplier, _xlpm.StellarReactionBase, _xlpm.Reaction_Bonus, _xlpm.EM_Bonus, _xlpm.Reaction_AdditiveBaseDMGBonus, _xlpm.Elevation_Multiplier, _xlpm.RES_Multiplier ) ))} -> 907.03 | T6: 19562.263 | U6: 63351.803 | V6: 1.5784 | W6: 1.3984 | X6: 0.18 | Y6: 2.5983 | Z6: 2.0983 | AA6: 0.5 | AB6: %ATK, %ATK, %CRIT_DMG | AC6: 0.932 | AD6: 0 | AE6: 0.622 | AF6: 0.4664 | AG6: 69.93 | AH6: 1.4763 | AI6: 179.93 | AJ6: 2338.6862 | AK6: 2.5983 | AL6: 2 | AM6: 1.615 | AN6: 1 | AO6: 0.14 | AP6: 0.4 | AQ6: 0.87164146 | AR6: 0 | AS6: 0 | AT6: 0.9
A7: %ATK | B7: %ATK | C7: %CRIT_DMG | D7: 7 | E7: 1 | F7: 22 | G7: =_xlfn.LET( _xlpm.BaseATK, Calculator!$B$26, _xlpm.MainStats, artifact_substat_cases[[#This Row],[Sands_Main]:[Circlet_Main]], _xlpm.ATK_Main,COUNTIF(_xlpm.MainStats,"%ATK")*46.6%, _xlpm.EM_Main,COUNTIF(_xlpm.MainStats,"EM")*186.5, _xlpm.CRIT_DMG_Main,COUNTIF(_xlpm.MainStats,"%CRIT_DMG")*62.2%, _xlpm.ATK_Sub,artifact_substat_cases[[#This Row],[%ATK]]*5.83%, _xlpm.EM_Sub,artifact_substat_cases[[#This Row],[EM]]*23.31, _xlpm.CRIT_DMG_Sub,artifact_substat_cases[[#This Row],[%CRIT_DMG]]*7.77%, _xlpm.EM,(Calculator!$B$47+ _xlpm.EM_Sub+_xlpm.EM_Main), _xlpm.ATK,(_xlpm.BaseATK*(1 +_xlpm.ATK_Sub+_xlpm.ATK_Main +Calculator!$B$31) +Calculator!$B$36), _xlpm.CRIT_DMG,(Calculator!$B$48+ _xlpm.CRIT_DMG_Sub+_xlpm.CRIT_DMG_Main), _xlpm.BaseReactionCoefficient, Calculator!$C$62, _xlpm.Ability,Calculator!$C$63, _xlpm.BaseDMG_Multiplier, Calculator!$C$65, _xlpm.StellarReactionBase,Calculator!$C$66 +MIN(_xlpm.ATK/100*0.7%,14%), _xlpm.Reaction_Bonus,Calculator!$C$68, _xlpm.EM_Bonus, (6/(1+2000/(_xlpm.EM+MIN(_xlpm.ATK/100*8,160)))), _xlpm.Reaction_AdditiveBaseDMGBonus,Calculator!$C$70, _xlpm.Elevation_Multiplier,Calculator!$C$72, _xlpm.RES_Multiplier, Calculator!$C$73, _xlpm.BaseDamage, PRODUCT( _xlpm.BaseReactionCoefficient, _xlpm.Ability, _xlpm.ATK, _xlpm.BaseDMG_Multiplier, (1 +_xlpm.StellarReactionBase), (1 +_xlpm.EM_Bonus + _xlpm.Reaction_Bonus) ) +_xlpm.Reaction_AdditiveBaseDMGBonus, _xlpm.FinalDamage,PRODUCT( _xlpm.BaseDamage, (1 +_xlpm.Elevation_Multiplier), _xlpm.RES_Multiplier, (1 +_xlpm.CRIT_DMG) ), _xlpm.FinalDamage ) -> 62904.772 | I7: All | J7: 63315.159 | K7: %ATK | L7: %ATK | M7: %CRIT_DMG | N7: 10 | O7: 2 | P7: 18 | S7: {=_xlfn.LET( _xlpm.BaseATK, Calculator!$B$26, _xlpm.MainStats, $K7:$M7, _xlpm.ATK_Main,COUNTIF(_xlpm.MainStats,"%ATK")*46.6%, _xlpm.EM_Main,COUNTIF(_xlpm.MainStats,"EM")*186.5, _xlpm.CRIT_DMG_Main,COUNTIF(_xlpm.MainStats,"%CRIT_DMG")*62.2%, _xlpm.ATK_Sub,$N7*5.83%, _xlpm.EM_Sub,$O7*23.31, _xlpm.CRIT_DMG_Sub,$P7*7.77%, _xlpm.Total_ATK_Buffs_Others, Calculator!$B$31, _xlpm.Total_CRIT_DMG_Buffs_Others, Calculator!$B$48, _xlpm.Total_ATK_Buffs_Artifacts, _xlpm.ATK_Sub+_xlpm.ATK_Main, _xlpm.Total_CRIT_DMG_Buffs_Artifacts, _xlpm.CRIT_DMG_Sub+_xlpm.CRIT_DMG_Main, _xlpm.Total_ATK_Buffs, (_xlpm.Total_ATK_Buffs_Artifacts + _xlpm.Total_ATK_Buffs_Others), _xlpm.Total_CRIT_DMG_Buffs, (_xlpm.Total_CRIT_DMG_Buffs_Artifacts + _xlpm.Total_CRIT_DMG_Buffs_Others), _xlpm.EM,(Calculator!$B$47+ _xlpm.EM_Sub+_xlpm.EM_Main), _xlpm.ATK,(_xlpm.BaseATK*(1 +_xlpm.Total_ATK_Buffs) +Calculator!$B$36), _xlpm.CRIT_DMG,(_xlpm.Total_CRIT_DMG_Buffs), _xlpm.BaseReactionCoefficient, Calculator!$C$62, _xlpm.Ability,Calculator!$C$63, _xlpm.BaseDMG_Multiplier, Calculator!$C$65, _xlpm.StellarReactionBase,Calculator!$C$66 +MIN(_xlpm.ATK/100*0.7%,14%), _xlpm.Reaction_Bonus,Calculator!$C$68, _xlpm.EM_Bonus, (6/(1+2000/(_xlpm.EM+MIN(_xlpm.ATK/100*8,160)))), _xlpm.Reaction_AdditiveBaseDMGBonus,Calculator!$C$70, _xlpm.Elevation_Multiplier,Calculator!$C$72, _xlpm.RES_Multiplier, Calculator!$C$73, _xlpm.BaseDamage, PRODUCT( _xlpm.BaseReactionCoefficient, _xlpm.Ability, _xlpm.ATK, _xlpm.BaseDMG_Multiplier, (1+_xlpm.StellarReactionBase), (1+_xlpm.EM_Bonus+_xlpm.Reaction_Bonus) )+_xlpm.Reaction_AdditiveBaseDMGBonus, _xlpm.FinalDamage, PRODUCT( _xlpm.BaseDamage, (1+_xlpm.Elevation_Multiplier), _xlpm.RES_Multiplier, (1+_xlpm.CRIT_DMG) ), TRANSPOSE(_xlfn.VSTACK( _xlpm.BaseATK, _xlpm.BaseDamage, _xlpm.FinalDamage, _xlpm.Total_ATK_Buffs, _xlpm.Total_ATK_Buffs_Artifacts, _xlpm.Total_ATK_Buffs_Others, _xlpm.Total_CRIT_DMG_Buffs, _xlpm.Total_CRIT_DMG_Buffs_Artifacts, _xlpm.Total_CRIT_DMG_Buffs_Others, _xlfn.TEXTJOIN(", ",TRUE,_xlpm.MainStats), _xlpm.ATK_Main, _xlpm.EM_Main, _xlpm.CRIT_DMG_Main, _xlpm.ATK_Sub, _xlpm.EM_Sub, _xlpm.CRIT_DMG_Sub, _xlpm.EM, _xlpm.ATK, _xlpm.CRIT_DMG, _xlpm.BaseReactionCoefficient, _xlpm.Ability, _xlpm.BaseDMG_Multiplier, _xlpm.StellarReactionBase, _xlpm.Reaction_Bonus, _xlpm.EM_Bonus, _xlpm.Reaction_AdditiveBaseDMGBonus, _xlpm.Elevation_Multiplier, _xlpm.RES_Multiplier ) ))} -> 907.03 | T7: 19982.439 | U7: 63315.159 | V7: 1.695 | W7: 1.515 | X7: 0.18 | Y7: 2.5206 | Z7: 2.0206 | AA7: 0.5 | AB7: %ATK, %ATK, %CRIT_DMG | AC7: 0.932 | AD7: 0 | AE7: 0.622 | AF7: 0.583 | AG7: 46.62 | AH7: 1.3986 | AI7: 156.62 | AJ7: 2444.4459 | AK7: 2.5206 | AL7: 2 | AM7: 1.615 | AN7: 1 | AO7: 0.14 | AP7: 0.4 | AQ7: 0.82003954 | AR7: 0 | AS7: 0 | AT7: 0.9
A8: %ATK | B8: %ATK | C8: %CRIT_DMG | D8: 8 | E8: 1 | F8: 21 | G8: =_xlfn.LET( _xlpm.BaseATK, Calculator!$B$26, _xlpm.MainStats, artifact_substat_cases[[#This Row],[Sands_Main]:[Circlet_Main]], _xlpm.ATK_Main,COUNTIF(_xlpm.MainStats,"%ATK")*46.6%, _xlpm.EM_Main,COUNTIF(_xlpm.MainStats,"EM")*186.5, _xlpm.CRIT_DMG_Main,COUNTIF(_xlpm.MainStats,"%CRIT_DMG")*62.2%, _xlpm.ATK_Sub,artifact_substat_cases[[#This Row],[%ATK]]*5.83%, _xlpm.EM_Sub,artifact_substat_cases[[#This Row],[EM]]*23.31, _xlpm.CRIT_DMG_Sub,artifact_substat_cases[[#This Row],[%CRIT_DMG]]*7.77%, _xlpm.EM,(Calculator!$B$47+ _xlpm.EM_Sub+_xlpm.EM_Main), _xlpm.ATK,(_xlpm.BaseATK*(1 +_xlpm.ATK_Sub+_xlpm.ATK_Main +Calculator!$B$31) +Calculator!$B$36), _xlpm.CRIT_DMG,(Calculator!$B$48+ _xlpm.CRIT_DMG_Sub+_xlpm.CRIT_DMG_Main), _xlpm.BaseReactionCoefficient, Calculator!$C$62, _xlpm.Ability,Calculator!$C$63, _xlpm.BaseDMG_Multiplier, Calculator!$C$65, _xlpm.StellarReactionBase,Calculator!$C$66 +MIN(_xlpm.ATK/100*0.7%,14%), _xlpm.Reaction_Bonus,Calculator!$C$68, _xlpm.EM_Bonus, (6/(1+2000/(_xlpm.EM+MIN(_xlpm.ATK/100*8,160)))), _xlpm.Reaction_AdditiveBaseDMGBonus,Calculator!$C$70, _xlpm.Elevation_Multiplier,Calculator!$C$72, _xlpm.RES_Multiplier, Calculator!$C$73, _xlpm.BaseDamage, PRODUCT( _xlpm.BaseReactionCoefficient, _xlpm.Ability, _xlpm.ATK, _xlpm.BaseDMG_Multiplier, (1 +_xlpm.StellarReactionBase), (1 +_xlpm.EM_Bonus + _xlpm.Reaction_Bonus) ) +_xlpm.Reaction_AdditiveBaseDMGBonus, _xlpm.FinalDamage,PRODUCT( _xlpm.BaseDamage, (1 +_xlpm.Elevation_Multiplier), _xlpm.RES_Multiplier, (1 +_xlpm.CRIT_DMG) ), _xlpm.FinalDamage ) -> 63054.804 | J8: 63312.627 | K8: %ATK | L8: %ATK | M8: %CRIT_DMG | N8: 9 | O8: 2 | P8: 19 | S8: {=_xlfn.LET( _xlpm.BaseATK, Calculator!$B$26, _xlpm.MainStats, $K8:$M8, _xlpm.ATK_Main,COUNTIF(_xlpm.MainStats,"%ATK")*46.6%, _xlpm.EM_Main,COUNTIF(_xlpm.MainStats,"EM")*186.5, _xlpm.CRIT_DMG_Main,COUNTIF(_xlpm.MainStats,"%CRIT_DMG")*62.2%, _xlpm.ATK_Sub,$N8*5.83%, _xlpm.EM_Sub,$O8*23.31, _xlpm.CRIT_DMG_Sub,$P8*7.77%, _xlpm.Total_ATK_Buffs_Others, Calculator!$B$31, _xlpm.Total_CRIT_DMG_Buffs_Others, Calculator!$B$48, _xlpm.Total_ATK_Buffs_Artifacts, _xlpm.ATK_Sub+_xlpm.ATK_Main, _xlpm.Total_CRIT_DMG_Buffs_Artifacts, _xlpm.CRIT_DMG_Sub+_xlpm.CRIT_DMG_Main, _xlpm.Total_ATK_Buffs, (_xlpm.Total_ATK_Buffs_Artifacts + _xlpm.Total_ATK_Buffs_Others), _xlpm.Total_CRIT_DMG_Buffs, (_xlpm.Total_CRIT_DMG_Buffs_Artifacts + _xlpm.Total_CRIT_DMG_Buffs_Others), _xlpm.EM,(Calculator!$B$47+ _xlpm.EM_Sub+_xlpm.EM_Main), _xlpm.ATK,(_xlpm.BaseATK*(1 +_xlpm.Total_ATK_Buffs) +Calculator!$B$36), _xlpm.CRIT_DMG,(_xlpm.Total_CRIT_DMG_Buffs), _xlpm.BaseReactionCoefficient, Calculator!$C$62, _xlpm.Ability,Calculator!$C$63, _xlpm.BaseDMG_Multiplier, Calculator!$C$65, _xlpm.StellarReactionBase,Calculator!$C$66 +MIN(_xlpm.ATK/100*0.7%,14%), _xlpm.Reaction_Bonus,Calculator!$C$68, _xlpm.EM_Bonus, (6/(1+2000/(_xlpm.EM+MIN(_xlpm.ATK/100*8,160)))), _xlpm.Reaction_AdditiveBaseDMGBonus,Calculator!$C$70, _xlpm.Elevation_Multiplier,Calculator!$C$72, _xlpm.RES_Multiplier, Calculator!$C$73, _xlpm.BaseDamage, PRODUCT( _xlpm.BaseReactionCoefficient, _xlpm.Ability, _xlpm.ATK, _xlpm.BaseDMG_Multiplier, (1+_xlpm.StellarReactionBase), (1+_xlpm.EM_Bonus+_xlpm.Reaction_Bonus) )+_xlpm.Reaction_AdditiveBaseDMGBonus, _xlpm.FinalDamage, PRODUCT( _xlpm.BaseDamage, (1+_xlpm.Elevation_Multiplier), _xlpm.RES_Multiplier, (1+_xlpm.CRIT_DMG) ), TRANSPOSE(_xlfn.VSTACK( _xlpm.BaseATK, _xlpm.BaseDamage, _xlpm.FinalDamage, _xlpm.Total_ATK_Buffs, _xlpm.Total_ATK_Buffs_Artifacts, _xlpm.Total_ATK_Buffs_Others, _xlpm.Total_CRIT_DMG_Buffs, _xlpm.Total_CRIT_DMG_Buffs_Artifacts, _xlpm.Total_CRIT_DMG_Buffs_Others, _xlfn.TEXTJOIN(", ",TRUE,_xlpm.MainStats), _xlpm.ATK_Main, _xlpm.EM_Main, _xlpm.CRIT_DMG_Main, _xlpm.ATK_Sub, _xlpm.EM_Sub, _xlpm.CRIT_DMG_Sub, _xlpm.EM, _xlpm.ATK, _xlpm.CRIT_DMG, _xlpm.BaseReactionCoefficient, _xlpm.Ability, _xlpm.BaseDMG_Multiplier, _xlpm.StellarReactionBase, _xlpm.Reaction_Bonus, _xlpm.EM_Bonus, _xlpm.Reaction_AdditiveBaseDMGBonus, _xlpm.Elevation_Multiplier, _xlpm.RES_Multiplier ) ))} -> 907.03 | T8: 19550.166 | U8: 63312.627 | V8: 1.6367 | W8: 1.4567 | X8: 0.18 | Y8: 2.5983 | Z8: 2.0983 | AA8: 0.5 | AB8: %ATK, %ATK, %CRIT_DMG | AC8: 0.932 | AD8: 0 | AE8: 0.622 | AF8: 0.5247 | AG8: 46.62 | AH8: 1.4763 | AI8: 156.62 | AJ8: 2391.566 | AK8: 2.5983 | AL8: 2 | AM8: 1.615 | AN8: 1 | AO8: 0.14 | AP8: 0.4 | AQ8: 0.82003954 | AR8: 0 | AS8: 0 | AT8: 0.9
A9: %ATK | B9: %ATK | C9: %CRIT_DMG | D9: 6 | E9: 1 | F9: 23 | G9: =_xlfn.LET( _xlpm.BaseATK, Calculator!$B$26, _xlpm.MainStats, artifact_substat_cases[[#This Row],[Sands_Main]:[Circlet_Main]], _xlpm.ATK_Main,COUNTIF(_xlpm.MainStats,"%ATK")*46.6%, _xlpm.EM_Main,COUNTIF(_xlpm.MainStats,"EM")*186.5, _xlpm.CRIT_DMG_Main,COUNTIF(_xlpm.MainStats,"%CRIT_DMG")*62.2%, _xlpm.ATK_Sub,artifact_substat_cases[[#This Row],[%ATK]]*5.83%, _xlpm.EM_Sub,artifact_substat_cases[[#This Row],[EM]]*23.31, _xlpm.CRIT_DMG_Sub,artifact_substat_cases[[#This Row],[%CRIT_DMG]]*7.77%, _xlpm.EM,(Calculator!$B$47+ _xlpm.EM_Sub+_xlpm.EM_Main), _xlpm.ATK,(_xlpm.BaseATK*(1 +_xlpm.ATK_Sub+_xlpm.ATK_Main +Calculator!$B$31) +Calculator!$B$36), _xlpm.CRIT_DMG,(Calculator!$B$48+ _xlpm.CRIT_DMG_Sub+_xlpm.CRIT_DMG_Main), _xlpm.BaseReactionCoefficient, Calculator!$C$62, _xlpm.Ability,Calculator!$C$63, _xlpm.BaseDMG_Multiplier, Calculator!$C$65, _xlpm.StellarReactionBase,Calculator!$C$66 +MIN(_xlpm.ATK/100*0.7%,14%), _xlpm.Reaction_Bonus,Calculator!$C$68, _xlpm.EM_Bonus, (6/(1+2000/(_xlpm.EM+MIN(_xlpm.ATK/100*8,160)))), _xlpm.Reaction_AdditiveBaseDMGBonus,Calculator!$C$70, _xlpm.Elevation_Multiplier,Calculator!$C$72, _xlpm.RES_Multiplier, Calculator!$C$73, _xlpm.BaseDamage, PRODUCT( _xlpm.BaseReactionCoefficient, _xlpm.Ability, _xlpm.ATK, _xlpm.BaseDMG_Multiplier, (1 +_xlpm.StellarReactionBase), (1 +_xlpm.EM_Bonus + _xlpm.Reaction_Bonus) ) +_xlpm.Reaction_AdditiveBaseDMGBonus, _xlpm.FinalDamage,PRODUCT( _xlpm.BaseDamage, (1 +_xlpm.Elevation_Multiplier), _xlpm.RES_Multiplier, (1 +_xlpm.CRIT_DMG) ), _xlpm.FinalDamage ) -> 62695.717 | J9: 63306.1 | K9: %ATK | L9: %ATK | M9: %CRIT_DMG | N9: 10 | O9: 4 | P9: 16 | S9: {=_xlfn.LET( _xlpm.BaseATK, Calculator!$B$26, _xlpm.MainStats, $K9:$M9, _xlpm.ATK_Main,COUNTIF(_xlpm.MainStats,"%ATK")*46.6%, _xlpm.EM_Main,COUNTIF(_xlpm.MainStats,"EM")*186.5, _xlpm.CRIT_DMG_Main,COUNTIF(_xlpm.MainStats,"%CRIT_DMG")*62.2%, _xlpm.ATK_Sub,$N9*5.83%, _xlpm.EM_Sub,$O9*23.31, _xlpm.CRIT_DMG_Sub,$P9*7.77%, _xlpm.Total_ATK_Buffs_Others, Calculator!$B$31, _xlpm.Total_CRIT_DMG_Buffs_Others, Calculator!$B$48, _xlpm.Total_ATK_Buffs_Artifacts, _xlpm.ATK_Sub+_xlpm.ATK_Main, _xlpm.Total_CRIT_DMG_Buffs_Artifacts, _xlpm.CRIT_DMG_Sub+_xlpm.CRIT_DMG_Main, _xlpm.Total_ATK_Buffs, (_xlpm.Total_ATK_Buffs_Artifacts + _xlpm.Total_ATK_Buffs_Others), _xlpm.Total_CRIT_DMG_Buffs, (_xlpm.Total_CRIT_DMG_Buffs_Artifacts + _xlpm.Total_CRIT_DMG_Buffs_Others), _xlpm.EM,(Calculator!$B$47+ _xlpm.EM_Sub+_xlpm.EM_Main), _xlpm.ATK,(_xlpm.BaseATK*(1 +_xlpm.Total_ATK_Buffs) +Calculator!$B$36), _xlpm.CRIT_DMG,(_xlpm.Total_CRIT_DMG_Buffs), _xlpm.BaseReactionCoefficient, Calculator!$C$62, _xlpm.Ability,Calculator!$C$63, _xlpm.BaseDMG_Multiplier, Calculator!$C$65, _xlpm.StellarReactionBase,Calculator!$C$66 +MIN(_xlpm.ATK/100*0.7%,14%), _xlpm.Reaction_Bonus,Calculator!$C$68, _xlpm.EM_Bonus, (6/(1+2000/(_xlpm.EM+MIN(_xlpm.ATK/100*8,160)))), _xlpm.Reaction_AdditiveBaseDMGBonus,Calculator!$C$70, _xlpm.Elevation_Multiplier,Calculator!$C$72, _xlpm.RES_Multiplier, Calculator!$C$73, _xlpm.BaseDamage, PRODUCT( _xlpm.BaseReactionCoefficient, _xlpm.Ability, _xlpm.ATK, _xlpm.BaseDMG_Multiplier, (1+_xlpm.StellarReactionBase), (1+_xlpm.EM_Bonus+_xlpm.Reaction_Bonus) )+_xlpm.Reaction_AdditiveBaseDMGBonus, _xlpm.FinalDamage, PRODUCT( _xlpm.BaseDamage, (1+_xlpm.Elevation_Multiplier), _xlpm.RES_Multiplier, (1+_xlpm.CRIT_DMG) ), TRANSPOSE(_xlfn.VSTACK( _xlpm.BaseATK, _xlpm.BaseDamage, _xlpm.FinalDamage, _xlpm.Total_ATK_Buffs, _xlpm.Total_ATK_Buffs_Artifacts, _xlpm.Total_ATK_Buffs_Others, _xlpm.Total_CRIT_DMG_Buffs, _xlpm.Total_CRIT_DMG_Buffs_Artifacts, _xlpm.Total_CRIT_DMG_Buffs_Others, _xlfn.TEXTJOIN(", ",TRUE,_xlpm.MainStats), _xlpm.ATK_Main, _xlpm.EM_Main, _xlpm.CRIT_DMG_Main, _xlpm.ATK_Sub, _xlpm.EM_Sub, _xlpm.CRIT_DMG_Sub, _xlpm.EM, _xlpm.ATK, _xlpm.CRIT_DMG, _xlpm.BaseReactionCoefficient, _xlpm.Ability, _xlpm.BaseDMG_Multiplier, _xlpm.StellarReactionBase, _xlpm.Reaction_Bonus, _xlpm.EM_Bonus, _xlpm.Reaction_AdditiveBaseDMGBonus, _xlpm.Elevation_Multiplier, _xlpm.RES_Multiplier ) ))} -> 907.03 | T9: 20902.208 | U9: 63306.1 | V9: 1.695 | W9: 1.515 | X9: 0.18 | Y9: 2.3652 | Z9: 1.8652 | AA9: 0.5 | AB9: %ATK, %ATK, %CRIT_DMG | AC9: 0.932 | AD9: 0 | AE9: 0.622 | AF9: 0.583 | AG9: 93.24 | AH9: 1.2432 | AI9: 203.24 | AJ9: 2444.4459 | AK9: 2.3652 | AL9: 2 | AM9: 1.615 | AN9: 1 | AO9: 0.14 | AP9: 0.4 | AQ9: 0.92222542 | AR9: 0 | AS9: 0 | AT9: 0.9
A10: %ATK | B10: %ATK | C10: %CRIT_DMG | D10: 11 | E10: 0 | F10: 19 | G10: =_xlfn.LET( _xlpm.BaseATK, Calculator!$B$26, _xlpm.MainStats, artifact_substat_cases[[#This Row],[Sands_Main]:[Circlet_Main]], _xlpm.ATK_Main,COUNTIF(_xlpm.MainStats,"%ATK")*46.6%, _xlpm.EM_Main,COUNTIF(_xlpm.MainStats,"EM")*186.5, _xlpm.CRIT_DMG_Main,COUNTIF(_xlpm.MainStats,"%CRIT_DMG")*62.2%, _xlpm.ATK_Sub,artifact_substat_cases[[#This Row],[%ATK]]*5.83%, _xlpm.EM_Sub,artifact_substat_cases[[#This Row],[EM]]*23.31, _xlpm.CRIT_DMG_Sub,artifact_substat_cases[[#This Row],[%CRIT_DMG]]*7.77%, _xlpm.EM,(Calculator!$B$47+ _xlpm.EM_Sub+_xlpm.EM_Main), _xlpm.ATK,(_xlpm.BaseATK*(1 +_xlpm.ATK_Sub+_xlpm.ATK_Main +Calculator!$B$31) +Calculator!$B$36), _xlpm.CRIT_DMG,(Calculator!$B$48+ _xlpm.CRIT_DMG_Sub+_xlpm.CRIT_DMG_Main), _xlpm.BaseReactionCoefficient, Calculator!$C$62, _xlpm.Ability,Calculator!$C$63, _xlpm.BaseDMG_Multiplier, Calculator!$C$65, _xlpm.StellarReactionBase,Calculator!$C$66 +MIN(_xlpm.ATK/100*0.7%,14%), _xlpm.Reaction_Bonus,Calculator!$C$68, _xlpm.EM_Bonus, (6/(1+2000/(_xlpm.EM+MIN(_xlpm.ATK/100*8,160)))), _xlpm.Reaction_AdditiveBaseDMGBonus,Calculator!$C$70, _xlpm.Elevation_Multiplier,Calculator!$C$72, _xlpm.RES_Multiplier, Calculator!$C$73, _xlpm.BaseDamage, PRODUCT( _xlpm.BaseReactionCoefficient, _xlpm.Ability, _xlpm.ATK, _xlpm.BaseDMG_Multiplier, (1 +_xlpm.StellarReactionBase), (1 +_xlpm.EM_Bonus + _xlpm.Reaction_Bonus) ) +_xlpm.Reaction_AdditiveBaseDMGBonus, _xlpm.FinalDamage,PRODUCT( _xlpm.BaseDamage, (1 +_xlpm.Elevation_Multiplier), _xlpm.RES_Multiplier, (1 +_xlpm.CRIT_DMG) ), _xlpm.FinalDamage ) -> 62944.36 | J10: 63298.155 | K10: %ATK | L10: %ATK | M10: %CRIT_DMG | N10: 7 | O10: 4 | P10: 19 | S10: {=_xlfn.LET( _xlpm.BaseATK, Calculator!$B$26, _xlpm.MainStats, $K10:$M10, _xlpm.ATK_Main,COUNTIF(_xlpm.MainStats,"%ATK")*46.6%, _xlpm.EM_Main,COUNTIF(_xlpm.MainStats,"EM")*186.5, _xlpm.CRIT_DMG_Main,COUNTIF(_xlpm.MainStats,"%CRIT_DMG")*62.2%, _xlpm.ATK_Sub,$N10*5.83%, _xlpm.EM_Sub,$O10*23.31, _xlpm.CRIT_DMG_Sub,$P10*7.77%, _xlpm.Total_ATK_Buffs_Others, Calculator!$B$31, _xlpm.Total_CRIT_DMG_Buffs_Others, Calculator!$B$48, _xlpm.Total_ATK_Buffs_Artifacts, _xlpm.ATK_Sub+_xlpm.ATK_Main, _xlpm.Total_CRIT_DMG_Buffs_Artifacts, _xlpm.CRIT_DMG_Sub+_xlpm.CRIT_DMG_Main, _xlpm.Total_ATK_Buffs, (_xlpm.Total_ATK_Buffs_Artifacts + _xlpm.Total_ATK_Buffs_Others), _xlpm.Total_CRIT_DMG_Buffs, (_xlpm.Total_CRIT_DMG_Buffs_Artifacts + _xlpm.Total_CRIT_DMG_Buffs_Others), _xlpm.EM,(Calculator!$B$47+ _xlpm.EM_Sub+_xlpm.EM_Main), _xlpm.ATK,(_xlpm.BaseATK*(1 +_xlpm.Total_ATK_Buffs) +Calculator!$B$36), _xlpm.CRIT_DMG,(_xlpm.Total_CRIT_DMG_Buffs), _xlpm.BaseReactionCoefficient, Calculator!$C$62, _xlpm.Ability,Calculator!$C$63, _xlpm.BaseDMG_Multiplier, Calculator!$C$65, _xlpm.StellarReactionBase,Calculator!$C$66 +MIN(_xlpm.ATK/100*0.7%,14%), _xlpm.Reaction_Bonus,Calculator!$C$68, _xlpm.EM_Bonus, (6/(1+2000/(_xlpm.EM+MIN(_xlpm.ATK/100*8,160)))), _xlpm.Reaction_AdditiveBaseDMGBonus,Calculator!$C$70, _xlpm.Elevation_Multiplier,Calculator!$C$72, _xlpm.RES_Multiplier, Calculator!$C$73, _xlpm.BaseDamage, PRODUCT( _xlpm.BaseReactionCoefficient, _xlpm.Ability, _xlpm.ATK, _xlpm.BaseDMG_Multiplier, (1+_xlpm.StellarReactionBase), (1+_xlpm.EM_Bonus+_xlpm.Reaction_Bonus) )+_xlpm.Reaction_AdditiveBaseDMGBonus, _xlpm.FinalDamage, PRODUCT( _xlpm.BaseDamage, (1+_xlpm.Elevation_Multiplier), _xlpm.RES_Multiplier, (1+_xlpm.CRIT_DMG) ), TRANSPOSE(_xlfn.VSTACK( _xlpm.BaseATK, _xlpm.BaseDamage, _xlpm.FinalDamage, _xlpm.Total_ATK_Buffs, _xlpm.Total_ATK_Buffs_Artifacts, _xlpm.Total_ATK_Buffs_Others, _xlpm.Total_CRIT_DMG_Buffs, _xlpm.Total_CRIT_DMG_Buffs_Artifacts, _xlpm.Total_CRIT_DMG_Buffs_Others, _xlfn.TEXTJOIN(", ",TRUE,_xlpm.MainStats), _xlpm.ATK_Main, _xlpm.EM_Main, _xlpm.CRIT_DMG_Main, _xlpm.ATK_Sub, _xlpm.EM_Sub, _xlpm.CRIT_DMG_Sub, _xlpm.EM, _xlpm.ATK, _xlpm.CRIT_DMG, _xlpm.BaseReactionCoefficient, _xlpm.Ability, _xlpm.BaseDMG_Multiplier, _xlpm.StellarReactionBase, _xlpm.Reaction_Bonus, _xlpm.EM_Bonus, _xlpm.Reaction_AdditiveBaseDMGBonus, _xlpm.Elevation_Multiplier, _xlpm.RES_Multiplier ) ))} -> 907.03 | T10: 19545.698 | U10: 63298.155 | V10: 1.5201 | W10: 1.3401 | X10: 0.18 | Y10: 2.5983 | Z10: 2.0983 | AA10: 0.5 | AB10: %ATK, %ATK, %CRIT_DMG | AC10: 0.932 | AD10: 0 | AE10: 0.622 | AF10: 0.4081 | AG10: 93.24 | AH10: 1.4763 | AI10: 203.24 | AJ10: 2285.8063 | AK10: 2.5983 | AL10: 2 | AM10: 1.615 | AN10: 1 | AO10: 0.14 | AP10: 0.4 | AQ10: 0.92222542 | AR10: 0 | AS10: 0 | AT10: 0.9
A11: %ATK | B11: %ATK | C11: %CRIT_DMG | D11: 9 | E11: 1 | F11: 20 | G11: =_xlfn.LET( _xlpm.BaseATK, Calculator!$B$26, _xlpm.MainStats, artifact_substat_cases[[#This Row],[Sands_Main]:[Circlet_Main]], _xlpm.ATK_Main,COUNTIF(_xlpm.MainStats,"%ATK")*46.6%, _xlpm.EM_Main,COUNTIF(_xlpm.MainStats,"EM")*186.5, _xlpm.CRIT_DMG_Main,COUNTIF(_xlpm.MainStats,"%CRIT_DMG")*62.2%, _xlpm.ATK_Sub,artifact_substat_cases[[#This Row],[%ATK]]*5.83%, _xlpm.EM_Sub,artifact_substat_cases[[#This Row],[EM]]*23.31, _xlpm.CRIT_DMG_Sub,artifact_substat_cases[[#This Row],[%CRIT_DMG]]*7.77%, _xlpm.EM,(Calculator!$B$47+ _xlpm.EM_Sub+_xlpm.EM_Main), _xlpm.ATK,(_xlpm.BaseATK*(1 +_xlpm.ATK_Sub+_xlpm.ATK_Main +Calculator!$B$31) +Calculator!$B$36), _xlpm.CRIT_DMG,(Calculator!$B$48+ _xlpm.CRIT_DMG_Sub+_xlpm.CRIT_DMG_Main), _xlpm.BaseReactionCoefficient, Calculator!$C$62, _xlpm.Ability,Calculator!$C$63, _xlpm.BaseDMG_Multiplier, Calculator!$C$65, _xlpm.StellarReactionBase,Calculator!$C$66 +MIN(_xlpm.ATK/100*0.7%,14%), _xlpm.Reaction_Bonus,Calculator!$C$68, _xlpm.EM_Bonus, (6/(1+2000/(_xlpm.EM+MIN(_xlpm.ATK/100*8,160)))), _xlpm.Reaction_AdditiveBaseDMGBonus,Calculator!$C$70, _xlpm.Elevation_Multiplier,Calculator!$C$72, _xlpm.RES_Multiplier, Calculator!$C$73, _xlpm.BaseDamage, PRODUCT( _xlpm.BaseReactionCoefficient, _xlpm.Ability, _xlpm.ATK, _xlpm.BaseDMG_Multiplier, (1 +_xlpm.StellarReactionBase), (1 +_xlpm.EM_Bonus + _xlpm.Reaction_Bonus) ) +_xlpm.Reaction_AdditiveBaseDMGBonus, _xlpm.FinalDamage,PRODUCT( _xlpm.BaseDamage, (1 +_xlpm.Elevation_Multiplier), _xlpm.RES_Multiplier, (1 +_xlpm.CRIT_DMG) ), _xlpm.FinalDamage ) -> 63145.811 | J11: 63288.994 | K11: %ATK | L11: %ATK | M11: %CRIT_DMG | N11: 8 | O11: 5 | P11: 17
